<?xml version="1.0" encoding="UTF-8"?>
<!-- Generated by org.testng.reporters.JUnitReportReporter -->
<testsuite skipped="0" hostname="DESKTOP-BPKQ36I" name="com.training.medium.tests.TC5_031InvalidLogin" tests="5" failures="1" timestamp="2019-12-04T12:38:52 IST" time="93.970" errors="0">
  <testcase name="validRegistrationTest" time="22.000" classname="com.training.medium.tests.TC5_031InvalidLogin"/>
  <testcase name="invalidLogin1" time="17.609" classname="com.training.medium.tests.TC5_031InvalidLogin"/>
  <testcase name="invalidLogin1" time="19.067" classname="com.training.medium.tests.TC5_031InvalidLogin"/>
  <testcase name="invalidLogin1" time="17.761" classname="com.training.medium.tests.TC5_031InvalidLogin">
    <failure type="java.lang.AssertionError" message="expected [Warning: Your account has exceeded allowed number of login attempts. Please try again in 1 hour.] but found [Warning: No match for E-Mail Address and/or Password.]">
      <![CDATA[java.lang.AssertionError: expected [Warning: Your account has exceeded allowed number of login attempts. Please try again in 1 hour.] but found [Warning: No match for E-Mail Address and/or Password.]
at org.testng.Assert.fail(Assert.java:97)
at org.testng.Assert.assertEqualsImpl(Assert.java:136)
at org.testng.Assert.assertEquals(Assert.java:118)
at org.testng.Assert.assertEquals(Assert.java:575)
at org.testng.Assert.assertEquals(Assert.java:585)
at com.training.pom.LoginPOM.invalidLogin(LoginPOM.java:63)
at com.training.medium.tests.TC5_031InvalidLogin.invalidLogin1(TC5_031InvalidLogin.java:113)
at sun.reflect.NativeMethodAccessorImpl.invoke0(Native Method)
at sun.reflect.NativeMethodAccessorImpl.invoke(Unknown Source)
at sun.reflect.DelegatingMethodAccessorImpl.invoke(Unknown Source)
at java.lang.reflect.Method.invoke(Unknown Source)
at org.testng.internal.MethodInvocationHelper.invokeMethod(MethodInvocationHelper.java:133)
at org.testng.internal.TestInvoker.invokeMethod(TestInvoker.java:584)
at org.testng.internal.TestInvoker.invokeTestMethod(TestInvoker.java:172)
at org.testng.internal.MethodRunner.runInSequence(MethodRunner.java:46)
at org.testng.internal.TestInvoker$MethodInvocationAgent.invoke(TestInvoker.java:804)
at org.testng.internal.TestInvoker.invokeTestMethods(TestInvoker.java:145)
at org.testng.internal.TestMethodWorker.invokeTestMethods(TestMethodWorker.java:146)
at org.testng.internal.TestMethodWorker.run(TestMethodWorker.java:128)
at java.util.ArrayList.forEach(Unknown Source)
at org.testng.TestRunner.privateRun(TestRunner.java:770)
at org.testng.TestRunner.run(TestRunner.java:591)
at org.testng.SuiteRunner.runTest(SuiteRunner.java:402)
at org.testng.SuiteRunner.runSequentially(SuiteRunner.java:396)
at org.testng.SuiteRunner.privateRun(SuiteRunner.java:355)
at org.testng.SuiteRunner.run(SuiteRunner.java:304)
at org.testng.SuiteRunnerWorker.runSuite(SuiteRunnerWorker.java:53)
at org.testng.SuiteRunnerWorker.run(SuiteRunnerWorker.java:96)
at org.testng.TestNG.runSuitesSequentially(TestNG.java:1180)
at org.testng.TestNG.runSuitesLocally(TestNG.java:1102)
at org.testng.TestNG.runSuites(TestNG.java:1032)
at org.testng.TestNG.run(TestNG.java:1000)
at org.testng.remote.AbstractRemoteTestNG.run(AbstractRemoteTestNG.java:115)
at org.testng.remote.RemoteTestNG.initAndRun(RemoteTestNG.java:251)
at org.testng.remote.RemoteTestNG.main(RemoteTestNG.java:77)
]]>
    </failure>
  </testcase> <!-- invalidLogin1 -->
  <testcase name="invalidLogin1" time="17.533" classname="com.training.medium.tests.TC5_031InvalidLogin"/>
</testsuite> <!-- com.training.medium.tests.TC5_031InvalidLogin -->
